Workbook

Sheet Instruções
B3: FERRAMENTA DE DIMENSIONAMENTO
B4: LINHA DE VIDA HORIZONTAL · Sistema de Proteção Individual Contra Quedas (SPIQ)
B5: Conforme NR-35 · NR-18 · ABNT NBR 16325-1/2 · ABNT NBR 8800
B17: GD ENGENHARIA E PERÍCIA LTDA
B18: Cálculo Estrutural · Avaliação de Imóveis · Perícia — CNPJ 54.705.748/0001-19
B19: Eng. Civil Gustavo Francisco Floriano Domingos · CREA 140.964-D/PR · (43) 9 9925-9577
B21: COMO USAR ESTA FERRAMENTA
B22: 1. Vá à aba «Entrada de Dados» e preencha as células AZUIS (sobre fundo amarelo). Use as listas suspensas — elas evitam erros.
B23: 2. Escolha o CENÁRIO (cobertura, estrutura ou solo); a lista de substratos se ajusta automaticamente.
B24: 3. Consulte a aba «Compatibilidade» para confirmar o tipo de ancoragem adequado ao seu substrato.
B25: 4. Veja os resultados na aba «Cálculo»: tração, flecha, ZLQ, verificação do cabo e dimensionamento do poste — tudo automático.
B26: 5. Ajuste o vão, a bitola do cabo, o absorvedor ou o perfil do poste até que o VEREDITO fique «APROVADO» (verde).
... B29: O QUE CADA ABA CONTÉM
B30: Entrada de Dados | C30: Todos os dados do projeto (geometria, cabo, usuários, absorvedores, poste).
B31: Cálculo | C31: Memória de cálculo automática com todas as verificações normativas e o veredito.
B32: Compatibilidade | C32: Matriz substrato × ancoragem com as restrições normativas.
B33: Materiais | C33: Especificação técnica — opções Inox AISI 316 e Galvanizado.
B34: Resumo de Materiais | C34: Lista de materiais e de EPI (quantitativo) para compra.
B36: LEGENDA DE CORES
B37: Células AZUIS sobre fundo amarelo = entrada do usuário
B38: Texto VERDE = valor vinculado de outra aba (não editar)
B39: Texto PRETO = resultado calculado automaticamente
B40: Fundo VERDE = verificação APROVADA · Fundo VERMELHO = REPROVADA
B42: REFERÊNCIAS NORMATIVAS
B43: NR-35 — Trabalho em Altura. Item 35.6.7: força de impacto transmitida ao trabalhador ≤ 6 kN. Anexo I item 3.1.1: a estrutura de ancoragem deve resistir à força máxima aplicável.
B44: NR-18 — Segurança e Saúde no Trabalho na Indústria da Construção. Item 18.12.12.2: dispositivos de ancoragem ≥ 1.500 kgf (15 kN). Anexo II: cabos de aço (CR ≥ 5× a carga de trabalho) e de fibra sintética (CR ≥ 22 kN).
B45: ABNT NBR 16325-1/2 — Dispositivos de ancoragem para proteção contra quedas. Anexo C (Parte 2): cálculo da Zona Livre de Queda (ZLQ).
B46: ABNT NBR 8800 — Projeto de estruturas de aço e mistas de edifícios. Dimensionamento dos postes de ancoragem (γa1 = 1,10).
B64: RESPONSABILIDADE TÉCNICA
B65: Esta ferramenta auxilia o dimensionamento e NÃO substitui o julgamento do profissional legalmente habilitado. Os resultados devem ser conferidos, validados em campo e formalizados em projeto e memorial assinados, com a respectiva ART. A instalação deve ser executada por equipe capacitada e os ensaios de ancoragem realizados conforme NR-35/NBR 16325. © GD Engenharia e Perícia Ltda.

Sheet Entrada de Dados
B2: ENTRADA DE DADOS
B3: Preencha as células AZUIS. As listas suspensas evitam erros. Os cálculos são automáticos na aba «Cálculo».
B4: 1 · IDENTIFICAÇÃO DO PROJETO
B5: Obra / Cliente | D5: Cobertura metálica — Maxi Limpeza
B6: Local | D6: Av. Alberto Carazzai, 965 — Cornélio Procópio/PR
B7: Resp. técnico (Eng.) | D7: Gustavo F. F. Domingos — CREA 140.964-D/PR
B8: Data | D8: 24/06/2026
B10: 2 · CENÁRIO E SUBSTRATO
B11: Cenário | D11: Cobertura
B12: Substrato / cobertura | D12: Telha trapezoidal metálica
B13: Ambiente (corrosividade) | D13: Industrial/Litorâneo (C4-C5)
B15: 3 · GEOMETRIA DO SISTEMA
B16: Vão entre postes L | D16: 10 | E16: m
B17: Nº de vãos | D17: 3 | E17: un
B18: Altura do poste h | D18: 1.2 | E18: m
B19: Pé-direito livre disponível | D19: 8.5 | E19: m
B21: 4 · CABO DA LINHA DE VIDA
B22: Material do cabo | D22: Inox AISI 316
B23: Diâmetro Ø | D23: 10 | E23: mm
B24: Pré-tensão de instalação T₀ | D24: 1 | E24: kN
B26: 5 · USUÁRIOS E EPI
B27: Nº de usuários simultâneos n | D27: 1 | E27: un
B28: Força de impacto no trabalhador Fₜ | D28: 6 | E28: kN
B29: Tipo de talabarte | D29: Talabarte Y c/ absorvedor
B30: Queda livre H_ql | D30: 1.5 | E30: m
B31: Frenagem do absorvedor H_fr | D31: 1.75 | E31: m
B33: 6 · ABSORVEDOR DE ENERGIA DA LINHA (opcional)
B34: Possui absorvedor de linha? | D34: Sim
B35: Força de atuação F_abs | D35: 12 | E35: kN
B36: Curso do absorvedor de linha | D36: 0.5 | E36: m
B38: 7 · POSTE DE ANCORAGEM (caso fabricado)
B39: Perfil do poste | D39: SHS 100x100x6,3
B40: Coef. ponderação ações γf | D40: 1.4 | E40: —
B41: Nº de chumbadores | D41: 4 | E41: un
B42: Braço dos chumbadores d | D42: 0.18 | E42: m
B45: LEGENDA: células AZUIS sobre fundo amarelo = preenchimento do usuário • passe o mouse nos cantos vermelhos para ver as dicas

Sheet Cálculo
B2: MEMÓRIA DE CÁLCULO — LINHA DE VIDA HORIZONTAL
B3: Cálculo automático conforme NR-35, NR-18 (Anexo II), ABNT NBR 16325-1/2 e ABNT NBR 8800. Valores em VERDE são vínculos da aba Entrada de Dados.
B4: VEREDITO DO SISTEMA → | F4: =IF(AND(F_ok,FS_ok,ZLQ_ok,POST_ok),"APROVADO","REPROVADO — revisar dados") -> APROVADO
B6: 1 · DADOS DE ENTRADA (vínculos)
B7: L | C7: Vão entre postes | F7: ='Entrada de Dados'!$D$16 -> 10 | G7: m
B8: — | C8: Material do cabo | F8: ='Entrada de Dados'!$D$22 -> Inox AISI 316
B9: Ø | C9: Diâmetro do cabo | F9: ='Entrada de Dados'!$D$23 -> 10 | G9: mm
B10: E | C10: Módulo de elasticidade do cabo | F10: =VLOOKUP('Entrada de Dados'!$D$22&"|"&'Entrada de Dados'!$D$23,TabCabos,4,FALSE()) -> 120000 | G10: MPa
B11: A | C11: Área metálica do cabo | F11: =VLOOKUP('Entrada de Dados'!$D$22&"|"&'Entrada de Dados'!$D$23,TabCabos,5,FALSE()) -> 47 | G11: mm²
B12: F_rup | C12: Carga de ruptura do cabo (MBL) | F12: =VLOOKUP('Entrada de Dados'!$D$22&"|"&'Entrada de Dados'!$D$23,TabCabos,6,FALSE()) -> 63 | G12: kN
B13: T₀ | C13: Pré-tensão de instalação | F13: ='Entrada de Dados'!$D$24 -> 1 | G13: kN
B14: n | C14: Nº usuários simultâneos | F14: ='Entrada de Dados'!$D$27 -> 1 | G14: un
B15: Fₜ | C15: Força de impacto no trabalhador | F15: ='Entrada de Dados'!$D$28 -> 6 | G15: kN
B16: h | C16: Altura do poste | F16: ='Entrada de Dados'!$D$18 -> 1.2 | G16: m
B17: EA | C17: Rigidez axial do cabo (E·A) | F17: =$F$10*$F$11/1000 -> 5640 | G17: kN
B18: a | C18: Meio-vão (L/2) | F18: =$F$7/2 -> 5 | G18: m
B20: 2 · FORÇA NO TRABALHADOR (NR-35 35.6.7)
B21: Fₜ | C21: Força de impacto transmitida ao trabalhador | F21: =$F$15 -> 6 | G21: kN | H21: =IF($F$15<=6,"OK ≤ 6 kN","REPROVA > 6 kN") -> OK ≤ 6 kN
B22: Q | C22: Carga aplicada à linha (n · Fₜ) | F22: =$F$14*$F$15 -> 6 | G22: kN
B24: 3 · FLECHA E TRAÇÃO — equilíbrio + compatibilidade elástica (Newton-Raphson)
C25: Resolve Q = 2·T·senθ com T = T₀ + (2EA/L)·(√(a²+f²) − a). Itera a flecha f até convergir.
C26: i | D26: f_i (m) | E26: √(a²+f²) | F26: g(f_i) | G26: g'(f_i) | H26: f_(i+1) (m)
C27: 0 | D27: 0.3 | E27: =SQRT($F$18^2+$D$27^2) -> 5.0089919 | F27: =$F$22*SQRT($F$18^2+$D$27^2)/(2*$D$27)-$F$13-(2*$F$17/$F$7)*(SQRT($F$18^2+$D$27^2)-$F$18) -> 38.94704 | G27: =-$F$22*$F$18^2/(2*SQRT($F$18^2+$D$27^2)*$D$27^2)-2*$F$17*$D$27/($F$7*SQRT($F$18^2+$D$27^2)) -> -233.92598 | H27: =$D$27-($F$22*SQRT($F$18^2+$D$27^2)/(2*$D$27)-$F$13-(2*$F$17/$F$7)*(SQRT($F$18^2+$D$27^2)-$F$18))/(-$F$22*$F$18^2/(2*SQRT($F$18^2+$D$27^2)*$D$27^2)-2*$F$17*$D$27/($F$7*SQRT($F$18^2+$D$27^2))) -> 0.46649301
C28: 1 | D28: =$H$27 -> 0.46649301 | E28: =SQRT($F$18^2+$D$28^2) -> 5.0217144 | F28: =$F$22*SQRT($F$18^2+$D$28^2)/(2*$D$28)-$F$13-(2*$F$17/$F$7)*(SQRT($F$18^2+$D$28^2)-$F$18) -> 6.8006007 | G28: =-$F$22*$F$18^2/(2*SQRT($F$18^2+$D$28^2)*$D$28^2)-2*$F$17*$D$28/($F$7*SQRT($F$18^2+$D$28^2)) -> -173.41654 | H28: =$D$28-($F$22*SQRT($F$18^2+$D$28^2)/(2*$D$28)-$F$13-(2*$F$17/$F$7)*(SQRT($F$18^2+$D$28^2)-$F$18))/(-$F$22*$F$18^2/(2*SQRT($F$18^2+$D$28^2)*$D$28^2)-2*$F$17*$D$28/($F$7*SQRT($F$18^2+$D$28^2))) -> 0.50570842
C29: 2 | D29: =$H$28 -> 0.50570842 | E29: =SQRT($F$18^2+$D$29^2) -> 5.025509 | F29: =$F$22*SQRT($F$18^2+$D$29^2)/(2*$D$29)-$F$13-(2*$F$17/$F$7)*(SQRT($F$18^2+$D$29^2)-$F$18) -> 0.038502577 | G29: =-$F$22*$F$18^2/(2*SQRT($F$18^2+$D$29^2)*$D$29^2)-2*$F$17*$D$29/($F$7*SQRT($F$18^2+$D$29^2)) -> -171.86409 | H29: =$D$29-($F$22*SQRT($F$18^2+$D$29^2)/(2*$D$29)-$F$13-(2*$F$17/$F$7)*(SQRT($F$18^2+$D$29^2)-$F$18))/(-$F$22*$F$18^2/(2*SQRT($F$18^2+$D$29^2)*$D$29^2)-2*$F$17*$D$29/($F$7*SQRT($F$18^2+$D$29^2))) -> 0.50593245
C30: 3 | D30: =$H$29 -> 0.50593245 | E30: =SQRT($F$18^2+$D$30^2) -> 5.0255316 | F30: =$F$22*SQRT($F$18^2+$D$30^2)/(2*$D$30)-$F$13-(2*$F$17/$F$7)*(SQRT($F$18^2+$D$30^2)-$F$18) -> 2.4269787e-07 | G30: =-$F$22*$F$18^2/(2*SQRT($F$18^2+$D$30^2)*$D$30^2)-2*$F$17*$D$30/($F$7*SQRT($F$18^2+$D$30^2)) -> -171.86194 | H30: =$D$30-($F$22*SQRT($F$18^2+$D$30^2)/(2*$D$30)-$F$13-(2*$F$17/$F$7)*(SQRT($F$18^2+$D$30^2)-$F$18))/(-$F$22*$F$18^2/(2*SQRT($F$18^2+$D$30^2)*$D$30^2)-2*$F$17*$D$30/($F$7*SQRT($F$18^2+$D$30^2))) -> 0.50593245
C31: 4 | D31: =$H$30 -> 0.50593245 | E31: =SQRT($F$18^2+$D$31^2) -> 5.0255316 | F31: =$F$22*SQRT($F$18^2+$D$31^2)/(2*$D$31)-$F$13-(2*$F$17/$F$7)*(SQRT($F$18^2+$D$31^2)-$F$18) -> 0 | G31: =-$F$22*$F$18^2/(2*SQRT($F$18^2+$D$31^2)*$D$31^2)-2*$F$17*$D$31/($F$7*SQRT($F$18^2+$D$31^2)) -> -171.86194 | H31: =$D$31-($F$22*SQRT($F$18^2+$D$31^2)/(2*$D$31)-$F$13-(2*$F$17/$F$7)*(SQRT($F$18^2+$D$31^2)-$F$18))/(-$F$22*$F$18^2/(2*SQRT($F$18^2+$D$31^2)*$D$31^2)-2*$F$17*$D$31/($F$7*SQRT($F$18^2+$D$31^2))) -> 0.50593245
C32: 5 | D32: =$H$31 -> 0.50593245 | E32: =SQRT($F$18^2+$D$32^2) -> 5.0255316 | F32: =$F$22*SQRT($F$18^2+$D$32^2)/(2*$D$32)-$F$13-(2*$F$17/$F$7)*(SQRT($F$18^2+$D$32^2)-$F$18) -> 0 | G32: =-$F$22*$F$18^2/(2*SQRT($F$18^2+$D$32^2)*$D$32^2)-2*$F$17*$D$32/($F$7*SQRT($F$18^2+$D$32^2)) -> -171.86194 | H32: =$D$32-($F$22*SQRT($F$18^2+$D$32^2)/(2*$D$32)-$F$13-(2*$F$17/$F$7)*(SQRT($F$18^2+$D$32^2)-$F$18))/(-$F$22*$F$18^2/(2*SQRT($F$18^2+$D$32^2)*$D$32^2)-2*$F$17*$D$32/($F$7*SQRT($F$18^2+$D$32^2))) -> 0.50593245
C33: 6 | D33: =$H$32 -> 0.50593245 | E33: =SQRT($F$18^2+$D$33^2) -> 5.0255316 | F33: =$F$22*SQRT($F$18^2+$D$33^2)/(2*$D$33)-$F$13-(2*$F$17/$F$7)*(SQRT($F$18^2+$D$33^2)-$F$18) -> 0 | G33: =-$F$22*$F$18^2/(2*SQRT($F$18^2+$D$33^2)*$D$33^2)-2*$F$17*$D$33/($F$7*SQRT($F$18^2+$D$33^2)) -> -171.86194 | H33: =$D$33-($F$22*SQRT($F$18^2+$D$33^2)/(2*$D$33)-$F$13-(2*$F$17/$F$7)*(SQRT($F$18^2+$D$33^2)-$F$18))/(-$F$22*$F$18^2/(2*SQRT($F$18^2+$D$33^2)*$D$33^2)-2*$F$17*$D$33/($F$7*SQRT($F$18^2+$D$33^2))) -> 0.50593245
C34: 7 | D34: =$H$33 -> 0.50593245 | E34: =SQRT($F$18^2+$D$34^2) -> 5.0255316 | F34: =$F$22*SQRT($F$18^2+$D$34^2)/(2*$D$34)-$F$13-(2*$F$17/$F$7)*(SQRT($F$18^2+$D$34^2)-$F$18) -> 0 | G34: =-$F$22*$F$18^2/(2*SQRT($F$18^2+$D$34^2)*$D$34^2)-2*$F$17*$D$34/($F$7*SQRT($F$18^2+$D$34^2)) -> -171.86194 | H34: =$D$34-($F$22*SQRT($F$18^2+$D$34^2)/(2*$D$34)-$F$13-(2*$F$17/$F$7)*(SQRT($F$18^2+$D$34^2)-$F$18))/(-$F$22*$F$18^2/(2*SQRT($F$18^2+$D$34^2)*$D$34^2)-2*$F$17*$D$34/($F$7*SQRT($F$18^2+$D$34^2))) -> 0.50593245
B36: f_el | C36: Flecha elástica convergida | F36: =$H$34 -> 0.50593245 | G36: m
B37: T_el | C37: Tração elástica Q·√(a²+f²)/(2f) | F37: =$F$22*SQRT($F$18^2+$H$34^2)/(2*$H$34) -> 29.79962 | G37: kN
B38: abs? | C38: Absorvedor de linha ativo? | F38: =IF(AND('Entrada de Dados'!$D$34="Sim",$F$37>'Entrada de Dados'!$D$35),"SIM — limita T","NÃO") -> SIM — limita T
B39: T | C39: TRAÇÃO MÁXIMA NA LINHA | F39: =IF(AND('Entrada de Dados'!$D$34="Sim",$F$37>'Entrada de Dados'!$D$35),'Entrada de Dados'!$D$35,$F$37) -> 12 | G39: kN
B40: senθ | C40: Seno do ângulo no apoio | F40: =$F$22/(2*$F$39) -> 0.25 | G40: —
B41: θ | C41: Ângulo da linha com a horizontal | F41: =DEGREES(ASIN(MIN(0.999,$F$40))) -> 14.477512 | G41: graus
B42: f_g | C42: Flecha sob carga (a·tanθ) | F42: =$F$18*TAN(RADIANS($F$41)) -> 1.2909944 | G42: m
B43: Δabs | C43: Curso do absorvedor de linha (se ativo) | F43: =IF(AND('Entrada de Dados'!$D$34="Sim",$F$37>'Entrada de Dados'!$D$35),'Entrada de Dados'!$D$36,0) -> 0.5 | G43: m
B44: f_tot | C44: FLECHA TOTAL (f_g + Δabs) | F44: =$F$42+$F$43 -> 1.7909944 | G44: m
B46: 4 · ZONA LIVRE DE QUEDA — ZLQ (NBR 16325-2 Anexo C)
...

Sheet Compatibilidade
B2: COMPATIBILIDADE SUBSTRATO × ANCORAGEM
B3: Matriz de seleção do tipo de ancoragem conforme a cobertura/estrutura a proteger. Consulte sempre as notas normativas ao final.
B5: SUBSTRATO ▼ / ANCORAGEM ▶ | C5: Suporte parafusado à terça/estr. | D5: Chapa/olhal SOLDADO (aço) | E5: Grampo / braçadeira (clamp) | F5: Chumbador QUÍMICO (concreto) | G5: Chumbador mecânico (concreto) | H5: Bloco de fundação (concreto) | I5: Poste cravado / estaiado
B6: Telha trapezoidal metálica | C6: ✔ | D6: ⚠ | E6: ⚠ | F6: – | G6: – | H6: – | I6: –
B7: Telha fibrocimento (frágil) | C7: ✔* | D7: – | E7: – | F7: – | G7: – | H7: – | I7: –
B8: Telha cerâmica (frágil) | C8: ✔* | D8: – | E8: – | F8: – | G8: – | H8: – | I8: –
B9: Telha termoacústica (sanduíche) | C9: ✔ | D9: ⚠ | E9: ⚠ | F9: – | G9: – | H9: – | I9: –
B10: Laje de concreto | C10: ✔ | D10: – | E10: – | F10: ✔ | G10: ⚠ | H10: – | I10: –
B11: Viga metálica (perfil I/H) | C11: ✔ | D11: ✔ | E11: ✔ | F11: – | G11: – | H11: – | I11: –
B12: Viga metálica (tubular) | C12: ✔ | D12: ✔ | E12: ⚠ | F12: – | G12: – | H12: – | I12: –
B13: Pilar de concreto | C13: ⚠ | D13: – | E13: – | F13: ✔ | G13: ⚠ | H13: – | I13: –
B14: Terça metálica | C14: ✔ | D14: ⚠ | E14: ✔ | F14: – | G14: – | H14: – | I14: –
B15: Solo coesivo | C15: – | D15: – | E15: – | F15: – | G15: – | H15: ✔ | I15: ⚠
B16: Solo arenoso | C16: – | D16: – | E16: – | F16: – | G16: – | H16: ✔ | I16: ✗
... B18: Talude protegido | C18: – | D18: – | E18: – | F18: – | G18: – | H18: ✔ | I18: ⚠
B20: LEGENDA
B21: ✔ | C21: Recomendado — solução usual e segura
B22: ✔* | C22: Recomendado SOMENTE com reforço sob a telha (a telha não recebe carga)
B23: ⚠ | C23: Com restrição — exige verificação adicional / detalhe específico
B24: ✗ | C24: Não permitido para esse substrato
B25: – | C25: Não aplicável
B27: NOTAS NORMATIVAS
B28: 1) Telhas frágeis (fibrocimento, cerâmica) NÃO podem receber carga concentrada — NR-18 18.7.8.2. A ancoragem deve transpassar a cobertura e fixar-se em estrutura resistente (terça/madeiramento/laje).
B29: 2) Em telha trapezoidal metálica, o suporte é parafusado à TERÇA (estrutura), nunca apenas à telha; usar vedação tipo EPDM nas perfurações e fixar na onda alta.
B30: 3) Concentração de carga em telhado/cobertura só é admitida se autorizada por profissional legalmente habilitado — NR-18 18.7.8.2 alínea (e).
B31: 4) Dispositivos de ancoragem devem resistir a ≥ 15 kN (1500 kgf) — NR-18 18.12.12.2 — e à força máxima aplicável — NR-35 Anexo I item 3.1.1.
B32: 5) Em aço, a chapa/olhal soldado deve ser executado por soldador qualificado, com solda dimensionada; o grampo (clamp) dispensa furação mas exige verificação de escorregamento.
B33: 6) Em concreto, o chumbador químico (epóxi) deve respeitar profundidade e distância de borda do fabricante; verificar arrancamento (cone de concreto).
B34: 7) Em solo/talude, os postes devem ser ancorados em blocos de fundação dimensionados ao tombamento/arrancamento; em solo arenoso evitar postes simplesmente cravados.
B35: 8) Materiais resistentes às intempéries: aço inoxidável (AISI 316) ou equivalente — NR-18 18.12.12.2 (d).

Sheet Materiais
B2: MATERIAIS — ESPECIFICAÇÃO TÉCNICA
B3: Duas opções: INOX AISI 316 (ambientes agressivos / litorâneos) e GALVANIZADO (melhor custo-benefício, ambientes abrigados).
B4: =CONCATENATE("Configuração de projeto selecionada: cabo Ø ",'Entrada de Dados'!$D$23,"mm · material ",'Entrada de Dados'!$D$22," · poste ",'Entrada de Dados'!$D$39) -> Configuração de projeto selecionada: cabo Ø 10mm · material Inox AISI 316 · poste SHS 100x100x6,3
B6: # | C6: Componente | D6: Opção 1 — INOX AISI 316 | E6: Opção 2 — GALVANIZADO (custo-benefício) | F6: Norma / Observação
B7: 1 | C7: Cabo de aço (linha de vida) | D7: Cabo inox AISI 316, construção 1x19 ou 7x19, Ø 8–12 mm conforme cálculo; CR ≥ 5× carga de trabalho. | E7: Cabo galvanizado a fogo 6x19 + alma de aço (AF), Ø 8–12 mm; CR ≥ 5× carga de trabalho. | F7: NR-18 Anexo II itens 3 e 11; NBR 16325.
B8: 2 | C8: Esticador / tensor | D8: Esticador inox 316 tipo gancho-olhal ou olhal-olhal, c/ contraporca; mesma CR do cabo. | E8: Esticador aço galvanizado tipo olhal-olhal c/ contraporca. | F8: Permite aplicar e manter a pré-tensão T₀.
B9: 3 | C9: Absorvedor de energia da linha | D9: Absorvedor inox/indeformável calibrado (atua ~9–15 kN), reduz a tração transmitida à estrutura. | E9: Absorvedor galvanizado calibrado (atua ~9–15 kN). | F9: NBR 16325; limita a carga nos postes.
B10: 4 | C10: Terminações do cabo | D10: Terminal prensado inox 316 ou laço c/ sapatilho + 3 clipes inox; sapatilho (thimble) inox. | E10: Terminal prensado galvanizado ou laço c/ sapatilho + clipes galvanizados. | F10: Fixação que impeça deslizamento — NR-18 Anexo II item 5.
B11: 5 | C11: Conectores / placas intermediárias | D11: Olhais e placas-guia inox 316 (passagem do cabo nos postes intermediários). | E11: Olhais e placas-guia aço galvanizado a fogo. | F11: Permitem deslizamento do trava-quedas.
B12: 6 | C12: Poste de ancoragem | D12: Perfil tubular SHS em inox 316 OU aço carbono galvanizado a fogo (zincagem ≥ 85 µm), conf. cálculo. | E12: Perfil tubular SHS em aço carbono (ASTM A572/A36) galvanizado a fogo. | F12: NBR 8800; dimensionado na aba Cálculo.
B13: 7 | C13: Placa de base + chumbadores | D13: Placa de aço inox/galv. + chumbadores inox 316 (químico/mecânico) — Ø conforme cálculo. | E13: Placa aço carbono galvanizada + chumbadores galvanizados/zincados. | F13: Resistência do dispositivo ≥ 15 kN — NR-18 18.12.12.2.
B14: 8 | C14: Vedação e acessórios | D14: Arruelas de vedação EPDM, mantas e selantes p/ perfurações em telhado. | E14: Idem. | F14: Estanqueidade da cobertura.
B15: 9 | C15: Placa de identificação | D15: Placa indelével: fabricante, CNPJ, modelo, nº série, material, carga, nº máx. de usuários, pictograma. | E15: Idem. | F15: NR-18 18.12.12.3 / NBR 16325.
B17: COMO ESCOLHER ENTRE INOX 316 E GALVANIZADO
B18: • INOX AISI 316: indicado para ambientes litorâneos, industriais, com maresia, respingos químicos ou alta umidade (categorias de corrosividade C4–C5). Maior durabilidade e menor manutenção; custo superior.
B19: • GALVANIZADO a fogo: melhor custo-benefício para ambientes internos/abrigados e atmosferas pouco agressivas (C2–C3). Exige inspeção periódica do revestimento de zinco e retoque em pontos de corte/solda.
B20: • Não misturar metais dissimilares em contato direto (par galvânico). Usar isoladores/buchas quando necessário.
B21: • As cargas de ruptura (CR) e as propriedades adotadas estão na aba «_aux» (tabela de cabos) e alimentam automaticamente o Cálculo.
B23: Referência comercial: linha de produtos Bonier ou equivalente técnico. Códigos e preços devem ser confirmados junto ao fornecedor na data da compra.

Sheet Resumo de Materiais
B2: RESUMO DE MATERIAIS E EPI
B3: Quantitativo para aquisição. As quantidades em VERDE são calculadas a partir da aba Entrada de Dados.
B4: ="Obra: "&'Entrada de Dados'!$D$5 -> Obra: Cobertura metálica — Maxi Limpeza | D4: ="Local: "&'Entrada de Dados'!$D$6 -> Local: Av. Alberto Carazzai, 965 — Cornélio Procópio/PR
B6: A · MATERIAIS DO SISTEMA DE ANCORAGEM
B7: Item | C7: Descrição | D7: Qtd. | E7: Unid. | F7: Observação
B8: 1 | C8: Poste de ancoragem (perfil tubular conf. Cálculo) | D8: =('Entrada de Dados'!$D$17+1) -> 4 | E8: un | F8: Extremos + intermediários
B9: 2 | C9: Placa de base + kit de chumbadores | D9: =('Entrada de Dados'!$D$17+1) -> 4 | E9: cj | F9: 1 por poste
B10: 3 | C10: Cabo de aço da linha de vida (Ø conf. Cálculo) | D10: =ROUND('Entrada de Dados'!$D$16*'Entrada de Dados'!$D$17*1.1,0) -> 33 | E10: m | F10: Vão × nº vãos + 10% de folga
B11: 4 | C11: Esticador / tensor com contraporca | D11: ='Entrada de Dados'!$D$17 -> 3 | E11: un | F11: Aplicação da pré-tensão
B12: 5 | C12: Absorvedor de energia da linha | D12: =IF('Entrada de Dados'!$D$34="Sim",'Entrada de Dados'!$D$17,0) -> 3 | E12: un | F12: 1 por tramo (se adotado)
B13: 6 | C13: Terminação prensada / laço + sapatilho + clipes | D13: =2*'Entrada de Dados'!$D$17 -> 6 | E13: cj | F13: Extremidades de cada tramo
B14: 7 | C14: Placa-guia / olhal intermediário | D14: =MAX(0,'Entrada de Dados'!$D$17-1) -> 2 | E14: un | F14: Postes intermediários
B15: 8 | C15: Placa de identificação do sistema | D15: =1 -> 1 | E15: un | F15: NR-18 18.12.12.3
B16: 9 | C16: Arruelas de vedação EPDM (telhado) | D16: =4*('Entrada de Dados'!$D$17+1) -> 16 | E16: un | F16: Estanqueidade das perfurações
B18: B · EQUIPAMENTOS DE PROTEÇÃO INDIVIDUAL (EPI) — por trabalhador
B19: Item | C19: Descrição | D19: Qtd. | E19: Unid. | F19: Norma / Observação
B20: 1 | C20: Cinturão de segurança tipo paraquedista (fixação dorsal e, se necessário, frontal) | D20: ='Entrada de Dados'!$D$27 -> 1 | E20: un | F20: NR-35 35.6.9 / CA vigente
B21: 2 | C21: Talabarte em Y com absorvedor de energia (garante Fₜ ≤ 6 kN) | D21: ='Entrada de Dados'!$D$27 -> 1 | E21: un | F21: NR-35 35.6.7
B22: 3 | C22: Trava-quedas deslizante guiado, compatível com o cabo da linha de vida | D22: ='Entrada de Dados'!$D$27 -> 1 | E22: un | F22: NR-18 Anexo II item 8
B23: 4 | C23: Capacete de segurança com jugular (fixação em 3 pontos) | D23: ='Entrada de Dados'!$D$27 -> 1 | E23: un | F23: NR-35 / NR-6
B24: 5 | C24: Conectores / mosquetões com dupla trava (rosca ou automática) | D24: =2*'Entrada de Dados'!$D$27 -> 2 | E24: un | F24: Resistência conforme fabricante
B25: 6 | C25: Calçado de segurança e luvas | D25: ='Entrada de Dados'!$D$27 -> 1 | E25: par | F25: Acessórios de proteção
B27: Todos os EPI devem possuir Certificado de Aprovação (CA) válido do MTE e ser inspecionados antes do uso (inspeção rotineira) e periodicamente — NR-35 35.6.6.
C30: _______________________________________
C31: ="Resp. técnico: "&'Entrada de Dados'!$D$7 -> Resp. técnico: Gustavo F. F. Domingos — CREA 140.964-D/PR

Sheet Memorial Descritivo
B5: MEMORIAL DESCRITIVO
B6: GD Engenharia e Perícia Ltda · CNPJ 54.705.748/0001-19 · Eng. Civil Gustavo F. F. Domingos · CREA 140.964-D/PR
B9: IDENTIFICAÇÃO
B10: Obra / Cliente | D10: ='Entrada de Dados'!$D$5 -> Cobertura metálica — Maxi Limpeza
B11: Local | D11: ='Entrada de Dados'!$D$6 -> Av. Alberto Carazzai, 965 — Cornélio Procópio/PR
B12: Responsável Técnico | D12: ='Entrada de Dados'!$D$7 -> Gustavo F. F. Domingos — CREA 140.964-D/PR
B13: Data | D13: ='Entrada de Dados'!$D$8 -> 24/06/2026
B15: 1 · OBJETO
B16: ="O presente memorial descritivo refere-se ao projeto da Linha de Vida Horizontal a ser instalada na obra "&'Entrada de Dados'!$D$5&", situada em "&'Entrada de Dados'!$D$6&". O sistema integra o conjunto de medidas de proteção contra quedas de altura (SPIQ), permitindo o deslocamento seguro de trabalhadores durante as atividades realizadas no local." -> O presente memorial descritivo refere-se ao projeto da Linha de Vida Horizontal a ser instalada na obra Cobertura metálica — Maxi Limpeza, situada em Av. Alberto Carazzai, 965 — Cornélio Procópio/PR. O sistema integra o conjunto de medidas de proteção contra quedas de altura (SPIQ), permitindo o deslocamento seguro de trabalhadores durante as atividades realizadas no local.
B18: 2 · NORMAS APLICÁVEIS
B19: ="O projeto observa a NR-35 (Trabalho em Altura), a NR-18 (Indústria da Construção), as ABNT NBR 16325-1 e 16325-2 (dispositivos de ancoragem) e a ABNT NBR 8800 (estruturas de aço), no que couber ao dimensionamento dos postes de ancoragem." -> O projeto observa a NR-35 (Trabalho em Altura), a NR-18 (Indústria da Construção), as ABNT NBR 16325-1 e 16325-2 (dispositivos de ancoragem) e a ABNT NBR 8800 (estruturas de aço), no que couber ao dimensionamento dos postes de ancoragem.
B21: 3 · DESCRIÇÃO DO LOCAL E CENÁRIO
B22: ="A instalação será executada "&IF('Entrada de Dados'!$D$11="Cobertura","sobre cobertura (telhado), com os postes de ancoragem fixados às terças ou à laje sob a telha",IF('Entrada de Dados'!$D$11="Estrutura","sobre estrutura metálica ou de concreto existente, com ancoragem por chapa soldada, grampo ou chumbador","em solo ou talude, com os postes apoiados em blocos de fundação de concreto dimensionados ao tombamento"))&". O substrato a proteger é do tipo "&'Entrada de Dados'!$D$12&". O ambiente foi classificado como "&'Entrada de Dados'!$D$13&", parâmetro que orienta a seleção do material dos componentes quanto à resistência à corrosão." -> A instalação será executada sobre cobertura (telhado), com os postes de ancoragem fixados às terças ou à laje sob a telha. O substrato a proteger é do tipo Telha trapezoidal metálica. O ambiente foi classificado como Industrial/Litorâneo (C4-C5), parâmetro que orienta a seleção do material dos componentes quanto à resistência à corrosão.
B24: 4 · DESCRIÇÃO DO SISTEMA PROPOSTO
B25: ="O sistema é composto por um cabo de aço tensionado entre "&SUBSTITUTE(TEXT(('Entrada de Dados'!$D$17+1),"0"),".",",")&" postes de ancoragem, distribuídos em "&SUBSTITUTE(TEXT('Entrada de Dados'!$D$17,"0"),".",",")&" vão(s) de "&SUBSTITUTE(TEXT('Entrada de Dados'!$D$16,"0.00"),".",",")&" m cada. Os postes têm altura de "&SUBSTITUTE(TEXT('Entrada de Dados'!$D$18,"0.00"),".",",")&" m acima da base. O cabo possui diâmetro de "&SUBSTITUTE(TEXT('Entrada de Dados'!$D$23,"0"),".",",")&" mm e é instalado com pré-tensão de "&SUBSTITUTE(TEXT('Entrada de Dados'!$D$24,"0.00"),".",",")&" kN. O trabalhador conecta-se ao cabo por trava-quedas deslizante, ligado ao cinturão tipo paraquedista por talabarte com absorvedor de energia." -> O sistema é composto por um cabo de aço tensionado entre 4 postes de ancoragem, distribuídos em 3 vão(s) de 10,00 m cada. Os postes têm altura de 1,20 m acima da base. O cabo possui diâmetro de 10 mm e é instalado com pré-tensão de 1,00 kN. O trabalhador conecta-se ao cabo por trava-quedas deslizante, ligado ao cinturão tipo paraquedista por talabarte com absorvedor de energia.
B27: 5 · MATERIAIS
B28: ="Os componentes (cabo, esticador, terminações, absorvedores, placas e postes) serão executados em "&IF(ISNUMBER(SEARCH("Inox",'Entrada de Dados'!$D$22)),"aço inoxidável AISI 316, recomendado para ambientes de maior agressividade (categorias de corrosividade C4–C5), por sua durabilidade e baixa manutenção","aço galvanizado a fogo, de melhor custo-benefício, adequado a ambientes abrigados e de menor agressividade (C2–C3), com inspeção periódica do revestimento")&". A especificação completa, com as duas alternativas de material, consta da aba «Materiais» desta ferramenta." -> Os componentes (cabo, esticador, terminações, absorvedores, placas e postes) serão executados em aço inoxidável AISI 316, recomendado para ambientes de maior agressividade (categorias de corrosividade C4–C5), por sua durabilidade e baixa manutenção. A especificação completa, com as duas alternativas de material, consta da aba «Materiais» desta ferramenta.
B30: 6 · SEGURANÇA E UTILIZAÇÃO
B31: ="A utilização do sistema exige o uso integral dos EPI especificados (cinturão paraquedista, talabarte com absorvedor, trava-quedas, capacete com jugular e conectores), todos com CA válido, além de capacitação dos trabalhadores conforme a NR-35. O sistema deve ser submetido a inspeções inicial e periódica." -> A utilização do sistema exige o uso integral dos EPI especificados (cinturão paraquedista, talabarte com absorvedor, trava-quedas, capacete com jugular e conectores), todos com CA válido, além de capacitação dos trabalhadores conforme a NR-35. O sistema deve ser submetido a inspeções inicial e periódica.
B44: Figura — Esquema geral da linha de vida horizontal.
B46: ASSINATURA
B47: ="A liberação para uso fica condicionada à correta instalação por equipe capacitada e à realização dos ensaios de carga das ancoragens (NR-35 / NBR 16325)." -> A liberação para uso fica condicionada à correta instalação por equipe capacitada e à realização dos ensaios de carga das ancoragens (NR-35 / NBR 16325).
B49: ="Cornélio Procópio/PR, "&'Entrada de Dados'!$D$8 -> Cornélio Procópio/PR, 24/06/2026
C51: _______________________________________
C52: ='Entrada de Dados'!$D$7 -> Gustavo F. F. Domingos — CREA 140.964-D/PR
C53: Engenheiro Civil — Responsável Técnico
C54: ART nº ____________________ · CREA-PR

Sheet Memorial de Cálculo
B5: MEMORIAL DE CÁLCULO
B6: GD Engenharia e Perícia Ltda · CNPJ 54.705.748/0001-19 · Eng. Civil Gustavo F. F. Domingos · CREA 140.964-D/PR
B9: IDENTIFICAÇÃO
B10: Obra / Cliente | D10: ='Entrada de Dados'!$D$5 -> Cobertura metálica — Maxi Limpeza
B11: Local | D11: ='Entrada de Dados'!$D$6 -> Av. Alberto Carazzai, 965 — Cornélio Procópio/PR
B12: Data | D12: ='Entrada de Dados'!$D$8 -> 24/06/2026
B14: 1 · PREMISSAS E CRITÉRIOS
B15: ="Adotam-se os seguintes critérios normativos: força de impacto transmitida ao trabalhador limitada a 6 kN (NR-35, item 35.6.7); fator de segurança dinâmico do cabo (carga de ruptura sobre tração) maior ou igual a 2; carga de ruptura do cabo de aço maior ou igual a 5 vezes a carga de trabalho (NR-18, Anexo II); dispositivo de ancoragem resistente a, no mínimo, 15 kN (NR-18, item 18.12.12.2); e coeficientes da NBR 8800 (γf = 1,40 e γa1 = 1,10) no dimensionamento dos postes." -> Adotam-se os seguintes critérios normativos: força de impacto transmitida ao trabalhador limitada a 6 kN (NR-35, item 35.6.7); fator de segurança dinâmico do cabo (carga de ruptura sobre tração) maior ou igual a 2; carga de ruptura do cabo de aço maior ou igual a 5 vezes a carga de trabalho (NR-18, Anexo II); dispositivo de ancoragem resistente a, no mínimo, 15 kN (NR-18, item 18.12.12.2); e coeficientes da NBR 8800 (γf = 1,40 e γa1 = 1,10) no dimensionamento dos postes.
B17: 2 · DADOS ADOTADOS
B18: ="Vão entre postes L = "&SUBSTITUTE(TEXT('Entrada de Dados'!$D$16,"0.00"),".",",")&" m; cabo de aço de diâmetro "&SUBSTITUTE(TEXT('Entrada de Dados'!$D$23,"0"),".",",")&" mm em "&'Entrada de Dados'!$D$22&", com carga de ruptura de "&SUBSTITUTE(TEXT(Cálculo!$F$12,"0.0"),".",",")&" kN e pré-tensão de instalação de "&SUBSTITUTE(TEXT('Entrada de Dados'!$D$24,"0.00"),".",",")&" kN. Número de usuários simultâneos n = "&SUBSTITUTE(TEXT('Entrada de Dados'!$D$27,"0"),".",",")&". Força de impacto no trabalhador Fₜ = "&SUBSTITUTE(TEXT('Entrada de Dados'!$D$28,"0.0"),".",",")&" kN. "&IF('Entrada de Dados'!$D$34="Sim","Foi adotado absorvedor de energia na linha, que limita a tração máxima a "&SUBSTITUTE(TEXT('Entrada de Dados'!$D$35,"0.0"),".",",")&" kN","Não foi adotado absorvedor de energia na linha")&"." -> Vão entre postes L = 10,00 m; cabo de aço de diâmetro 10 mm em Inox AISI 316, com carga de ruptura de 63,0 kN e pré-tensão de instalação de 1,00 kN. Número de usuários simultâneos n = 1. Força de impacto no trabalhador Fₜ = 6,0 kN. Foi adotado absorvedor de energia na linha, que limita a tração máxima a 12,0 kN.
B20: 3 · TRAÇÃO E FLECHA DA LINHA
B21: ="A carga aplicada à linha é Q = n × Fₜ = "&SUBSTITUTE(TEXT(Cálculo!$F$22,"0.0"),".",",")&" kN. Resolvendo o equilíbrio (Q = 2·T·senθ) com a compatibilidade elástica do cabo pelo método de Newton-Raphson, obtém-se a tração elástica de "&SUBSTITUTE(TEXT(Cálculo!$F$37,"0.00"),".",",")&" kN. "&IF('Entrada de Dados'!$D$34="Sim","Como o absorvedor de linha atua, a tração máxima é limitada a "&SUBSTITUTE(TEXT(Cálculo!$F$39,"0.00"),".",",")&" kN","A tração máxima resulta em "&SUBSTITUTE(TEXT(Cálculo!$F$39,"0.00"),".",",")&" kN")&", correspondente a um ângulo de "&SUBSTITUTE(TEXT(Cálculo!$F$41,"0.0"),".",",")&"° com a horizontal e flecha total de "&SUBSTITUTE(TEXT(Cálculo!$F$44,"0.00"),".",",")&" m." -> A carga aplicada à linha é Q = n × Fₜ = 6,0 kN. Resolvendo o equilíbrio (Q = 2·T·senθ) com a compatibilidade elástica do cabo pelo método de Newton-Raphson, obtém-se a tração elástica de 29,80 kN. Como o absorvedor de linha atua, a tração máxima é limitada a 12,00 kN, correspondente a um ângulo de 14,5° com a horizontal e flecha total de 1,79 m.
B23: 4 · ZONA LIVRE DE QUEDA (ZLQ)
B24: ="Conforme o Anexo C da NBR 16325-2, ZLQ = queda livre + frenagem + 1,5 m + 1,0 m + flecha. Resulta ZLQ = "&SUBSTITUTE(TEXT(Cálculo!$F$52,"0.00"),".",",")&" m, "&IF(Cálculo!$F$52<='Entrada de Dados'!$D$19,"valor INFERIOR ao pé-direito livre disponível de ","valor SUPERIOR ao pé-direito livre disponível de ")&SUBSTITUTE(TEXT('Entrada de Dados'!$D$19,"0.00"),".",",")&" m — "&IF(Cálculo!$F$52<='Entrada de Dados'!$D$19,"condição ATENDIDA.","condição NÃO ATENDIDA; rever vão, absorvedor ou ponto de ancoragem.") -> Conforme o Anexo C da NBR 16325-2, ZLQ = queda livre + frenagem + 1,5 m + 1,0 m + flecha. Resulta ZLQ = 7,54 m, valor INFERIOR ao pé-direito livre disponível de 8,50 m — condição ATENDIDA.
B26: 5 · VERIFICAÇÃO DO CABO
B27: ="O fator de segurança dinâmico é FS = carga de ruptura/tração = "&SUBSTITUTE(TEXT(Cálculo!$F$12,"0.0"),".",",")&" / "&SUBSTITUTE(TEXT(Cálculo!$F$39,"0.00"),".",",")&" = "&SUBSTITUTE(TEXT(Cálculo!$F$56,"0.00"),".",",")&" — "&IF(Cálculo!$F$56>=2,"superior ao mínimo de 2 (ATENDE).","inferior ao mínimo de 2 (NÃO ATENDE).") -> O fator de segurança dinâmico é FS = carga de ruptura/tração = 63,0 / 12,00 = 5,25 — superior ao mínimo de 2 (ATENDE).
B29: 6 · DIMENSIONAMENTO DO POSTE (NBR 8800)
B30: ="As reações no topo do poste extremo são H = T·cosθ = "&SUBSTITUTE(TEXT(Cálculo!$F$60,"0.00"),".",",")&" kN e V = T·senθ = "&SUBSTITUTE(TEXT(Cálculo!$F$61,"0.00"),".",",")&" kN, gerando momento na base M_k = H·h = "&SUBSTITUTE(TEXT(Cálculo!$F$63,"0.00"),".",",")&" kN·m. Adotado o perfil tubular "&'Entrada de Dados'!$D$39&" (fy = "&SUBSTITUTE(TEXT(Cálculo!$F$71,"0"),".",",")&" MPa), o momento resistente é M_Rd = "&SUBSTITUTE(TEXT(Cálculo!$F$76,"0.00"),".",",")&" kN·m e a utilização à flexo-compressão resulta em "&SUBSTITUTE(TEXT(Cálculo!$F$78,"0.00"),".",",")&" — "&IF(Cálculo!$F$78<=1,"inferior a 1,0 (ATENDE).","superior a 1,0 (NÃO ATENDE; aumentar a seção).") -> As reações no topo do poste extremo são H = T·cosθ = 11,62 kN e V = T·senθ = 3,00 kN, gerando momento na base M_k = H·h = 13,94 kN·m. Adotado o perfil tubular SHS 100x100x6,3 (fy = 345 MPa), o momento resistente é M_Rd = 26,06 kN·m e a utilização à flexo-compressão resulta em 0,75 — inferior a 1,0 (ATENDE).
B32: 7 · ANCORAGEM
B33: ="A tração de cálculo por chumbador é estimada em "&SUBSTITUTE(TEXT(Cálculo!$F$85,"0.0"),".",",")&" kN; o arrancamento no concreto/aço deve ser verificado conforme o fabricante. O dispositivo de ancoragem deve resistir a, no mínimo, "&SUBSTITUTE(TEXT(Cálculo!$F$86,"0.0"),".",",")&" kN, atendendo ao mínimo da NR-18 e à tração da linha." -> A tração de cálculo por chumbador é estimada em 54,2 kN; o arrancamento no concreto/aço deve ser verificado conforme o fabricante. O dispositivo de ancoragem deve resistir a, no mínimo, 15,0 kN, atendendo ao mínimo da NR-18 e à tração da linha.
B36: 8 · RESULTADOS CONSOLIDADOS
B37: Grandeza | F37: Símb. | G37: Resultado
B38: Tração máxima na linha | F38: T | G38: =SUBSTITUTE(TEXT(Cálculo!$F$39,"0.00"),".",",")&" kN" -> 12,00 kN
B39: Flecha total | F39: f | G39: =SUBSTITUTE(TEXT(Cálculo!$F$44,"0.00"),".",",")&" m" -> 1,79 m
B40: Zona Livre de Queda | F40: ZLQ | G40: =SUBSTITUTE(TEXT(Cálculo!$F$52,"0.00"),".",",")&" m" -> 7,54 m
B41: FS dinâmico do cabo | F41: FS | G41: =SUBSTITUTE(TEXT(Cálculo!$F$56,"0.00"),".",",") -> 5,25
B42: Momento na base do poste | F42: M_k | G42: =SUBSTITUTE(TEXT(Cálculo!$F$63,"0.00"),".",",")&" kN·m" -> 13,94 kN·m
B43: Utilização do poste | F43: util | G43: =SUBSTITUTE(TEXT(Cálculo!$F$78,"0.00"),".",",") -> 0,75
B45: 9 · CONCLUSÃO
B46: =Cálculo!F4 -> APROVADO
B48: ASSINATURA
B49: ="Este memorial é gerado automaticamente a partir dos dados de entrada e das verificações da aba «Cálculo». Os resultados devem ser conferidos e validados pelo responsável técnico antes da emissão e assinatura, com a respectiva ART." -> Este memorial é gerado automaticamente a partir dos dados de entrada e das verificações da aba «Cálculo». Os resultados devem ser conferidos e validados pelo responsável técnico antes da emissão e assinatura, com a respectiva ART.
B51: ="Cornélio Procópio/PR, "&'Entrada de Dados'!$D$8 -> Cornélio Procópio/PR, 24/06/2026
C53: _______________________________________
C54: ='Entrada de Dados'!$D$7 -> Gustavo F. F. Domingos — CREA 140.964-D/PR
C55: Engenheiro Civil — Responsável Técnico
C56: ART nº ____________________ · CREA-PR

Sheet _aux
A1: Cenarios | C1: Cobertura | D1: Estrutura | E1: Solo | G1: Materiais | H1: SimNao | I1: Talabarte | J1: Perfis | K1: Diam
A2: Cobertura | C2: Telha trapezoidal metálica | D2: Viga metálica (perfil I/H) | E2: Solo coesivo (bloco concreto) | G2: Inox AISI 316 | H2: Sim | I2: Talabarte Y c/ absorvedor | J2: SHS 80x80x6,3 | K2: 8
A3: Estrutura | C3: Telha fibrocimento | D3: Viga metálica (tubular) | E3: Solo arenoso (bloco concreto) | G3: Custo-benefício (galvanizado) | H3: Não | I3: Talabarte simples c/ absorvedor | J3: SHS 100x100x6,3 | K3: 10
A4: Solo | C4: Telha cerâmica | D4: Laje de concreto | E4: Rocha (chumbador) | I4: Trava-quedas retrátil | J4: SHS 100x100x8,0 | K4: 12
C5: Laje de concreto | D5: Pilar de concreto | E5: Talude protegido | J5: SHS 120x120x8,0
C6: Telha termoacústica (sanduíche) | D6: Terça metálica | E6: Poste cravado | J6: SHS 150x150x8,0
J7: SHS 150x150x10,0
A20: TabelaCabos
A21: Chave | B21: Material | C21: Ø (mm) | D21: E (MPa) | E21: A (mm²) | F21: MBL (kN) | G21: massa (kg/m)
A22: Inox AISI 316|8 | B22: Inox AISI 316 | C22: 8 | D22: 120000 | E22: 30 | F22: 40 | G22: 0.25
A23: Inox AISI 316|10 | B23: Inox AISI 316 | C23: 10 | D23: 120000 | E23: 47 | F23: 63 | G23: 0.39
A24: Inox AISI 316|12 | B24: Inox AISI 316 | C24: 12 | D24: 120000 | E24: 68 | F24: 90 | G24: 0.56
A25: Custo-benefício (galvanizado)|8 | B25: Galvanizado 6x19 | C25: 8 | D25: 100000 | E25: 31 | F25: 38 | G25: 0.23
A26: Custo-benefício (galvanizado)|10 | B26: Galvanizado 6x19 | C26: 10 | D26: 100000 | E26: 48 | F26: 59 | G26: 0.36
A27: Custo-benefício (galvanizado)|12 | B27: Galvanizado 6x19 | C27: 12 | D27: 100000 | E27: 69 | F27: 85 | G27: 0.52
A32: TabelaPerfis
A33: Perfil | B33: b (mm) | C33: t (mm) | D33: W (cm³) | E33: Z (cm³) | F33: A (cm²) | G33: fy (MPa)
A34: SHS 80x80x6,3 | B34: 80 | C34: 6.3 | D34: 42.3 | E34: 51.5 | F34: 18.6 | G34: 250
A35: SHS 100x100x6,3 | B35: 100 | C35: 6.3 | D35: 69.4 | E35: 83.1 | F35: 23.6 | G35: 345
A36: SHS 100x100x8,0 | B36: 100 | C36: 8 | D36: 83.7 | E36: 101.8 | F36: 29.4 | G36: 345
A37: SHS 120x120x8,0 | B37: 120 | C37: 8 | D37: 125.5 | E37: 150.8 | F37: 35.8 | G37: 345
A38: SHS 150x150x8,0 | B38: 150 | C38: 8 | D38: 204.3 | E38: 242.2 | F38: 45.4 | G38: 345
A39: SHS 150x150x10,0 | B39: 150 | C39: 10 | D39: 245.2 | E39: 294.5 | F39: 56 | G39: 345
